<mujoco>
    <body childclass="mz04" name="robot:base" pos="0 0 0">
        <inertial diaginertia="0.03 0.03 0.03" mass="0.1" pos="0 0 0"></inertial>
        <geom mesh="MZ04-Base_0" material="Opaque(191,191,191)" class="visual"/>
        <geom mesh="MZ04-Base_1" material="Opaque(34,34,34)" class="visual"/>
        <geom mesh="MZ04-Base_2" material="Opaque(60,60,60)" class="visual"/>
        <geom mesh="robot:base_link" name="robot:base"></geom>
        <body name="robot:j1_link" pos="0 0 0">
            <inertial diaginertia="0.03 0.03 0.03" mass="0.1" pos="0 0 0.17"></inertial>
            <joint axis="0 0 1" name="robot:j1_joint" pos="0 0 0.17"></joint>
            <geom mesh="MZ04-J1_0" material="Opaque(216,216,216)" class="visual"/>
            <geom mesh="MZ04-J1_1" material="Opaque(114,127,127)" class="visual"/>
            <geom mesh="robot:j1_link" name="robot:j1_link"></geom>
            <body name="robot:j2_link" pos="0 0 0">
                <inertial diaginertia="0.03 0.03 0.03" mass="0.1" pos="0 0 0.34"></inertial>
                <joint axis="0 -1 0" name="robot:j2_joint" pos="0 0 0.34" ref="90"></joint>
                <geom mesh="MZ04-J2_0" material="Opaque(216,216,216)" class="visual"/>
                <geom mesh="MZ04-J2_1" material="Opaque(114,127,127)" class="visual"/>
                <geom mesh="robot:j2_link" name="robot:j2_link"></geom>
                <body name="robot:j3_link" pos="0 0 0">
                    <inertial diaginertia="0.03 0.03 0.03" mass="0.1" pos="0 0 0.6"></inertial>
                    <joint axis="0 -1 0" name="robot:j3_joint" pos="0 0 0.6"></joint>
                    <geom mesh="MZ04-J3_0" material="Opaque(255,200,0)" class="visual"/>
                    <geom mesh="MZ04-J3_1" material="Opaque(216,216,216)" class="visual"/>
                    <geom mesh="robot:j3_link" name="robot:j3_link"></geom>
                    <body name="robot:j4_link" pos="0 0 0">
                        <inertial diaginertia="0.03 0.03 0.03" mass="0.1" pos="0.08 0 0.625"></inertial>
                        <joint axis="1 0 0" name="robot:j4_joint" pos="0.08 0 0.625"></joint>
                        <geom mesh="MZ04-J4_0" material="Opaque(255,0,0)" class="visual"/>
                        <geom mesh="MZ04-J4_1" material="Opaque(216,216,216)" class="visual"/>
                        <geom mesh="robot:j4_link" name="robot:j4_link"></geom>
                        <body name="robot:j5_link" pos="0 0 0">
                            <inertial diaginertia="0.03 0.03 0.03" mass="0.1" pos="0.28 0 0.625"></inertial>
                            <joint axis="0 -1 0" name="robot:j5_joint" pos="0.28 0 0.625"></joint>
                            <geom mesh="MZ04-J5_0" material="Opaque(216,216,216)" class="visual"/>
                            <geom mesh="MZ04-J5_1" material="Opaque(60,60,60)" class="visual"/>
                            <geom mesh="robot:j5_link" name="robot:j5_link"></geom>
                            <body name="robot:j6_link" pos="0 0 0">
                                <inertial diaginertia="0.03 0.03 0.03" mass="0.1" pos="0.35 0 0.625"></inertial>
                                <joint axis="1 0 0" name="robot:j6_joint" pos="0.35 0 0.625"></joint>
                                <geom mesh="MZ04-J6_0" material="Opaque(255,0,0)" class="visual"/>
                                <geom mesh="MZ04-J6_1" material="Opaque(60,60,60)" class="visual"/>
                                <geom mesh="robot:j6_link" name="robot:j6_link"></geom>
                                <body name="robot:end_effector_link" pos="0.362 0 0.625" euler="0 -90 0">
                                    <body name="robot:end_effector" pos="-0.03 -0.03 0">
                                        <geom mesh="robot:end_effector"></geom>
                                        <geom mesh="EndEffector_0" material="Opaque(176,176,176)" class="visual"/>
                                        <geom mesh="EndEffector_1" material="Opaque(63,63,63)" class="visual"/>
                                        <geom mesh="EndEffector_2" material="Opaque(255,239,173)" class="visual"/>
                                        <geom mesh="EndEffector_3" material="Opaque(203,210,238)" class="visual"/>
                                        <geom mesh="EndEffector_4" material="plastic_black" class="visual"/>
                                    </body>
                                    <camera name="robot:camera" pos="0.111 0.009 0.095" euler="0 0 -90" fovy="58"></camera>
                                    <camera name="robot:camera_right" pos="0.111 -0.009 0.095" euler="0 0 -90" fovy="58"></camera>
                                    <site name="robot:end_effector" pos="0.085 0 -0.039" rgba="1 0 1 0" size="0.002"></site>
                                    <body name="robot:ee_adhesion" pos="0.085 0 -0.039">
                                        <geom type="box" size="0.002 0.002 0.002" pos="0 0 0.002" class="mz04:end_effector"></geom>
                                    </body>
                                </body>
                            </body>
                        </body>
                    </body>
                </body>
            </body>
        </body>
    </body>
</mujoco>
